2023-07-06 13:11:04,862 DEBUG    root            Loaded Command Group: ['gcloud', 'projects']
2023-07-06 13:11:04,863 DEBUG    root            Loaded Command Group: ['gcloud', 'projects', 'describe']
2023-07-06 13:11:04,864 DEBUG    root            Running [gcloud.projects.describe] with arguments: [--account: "inel.pandzic@percona.com", --configuration: "percona-cloud-dev", --format: "value(name)", PROJECT_ID_OR_NUMBER: "cloud-dev-112233"]
2023-07-06 13:11:04,866 DEBUG    google.auth.transport.requests Making request: POST https://oauth2.googleapis.com/token
2023-07-06 13:11:04,870 DEBUG    urllib3.connectionpool Starting new HTTPS connection (1): oauth2.googleapis.com:443
2023-07-06 13:11:04,871 DEBUG    google.auth.transport.requests Making request: POST https://oauth2.googleapis.com/token
2023-07-06 13:11:04,871 DEBUG    urllib3.connectionpool Starting new HTTPS connection (2): oauth2.googleapis.com:443
2023-07-06 13:11:04,872 DEBUG    root            (gcloud.projects.describe) There was a problem refreshing your current auth tokens: HTTPSConnectionPool(host='oauth2.googleapis.com', port=443): Max retries exceeded with url: /token (Caused by NewConnectionError('<urllib3.connection.HTTPSConnection object at 0x106f47d10>: Failed to establish a new connection: [Errno 8] nodename nor servname provided, or not known'))
Please run:

  $ gcloud auth login

to obtain new credentials.

If you have already logged in with a different account:

    $ gcloud config set account ACCOUNT

to select an already authenticated account to use.
Traceback (most recent call last):
  File "/Users/inelpandzic/Dev/Workspace/tools/google-cloud-sdk/lib/third_party/urllib3/connection.py", line 174, in _new_conn
    conn = connection.create_connection(
           ^^^^^^^^^^^^^^^^^^^^^^^^^^^^^
  File "/Users/inelpandzic/Dev/Workspace/tools/google-cloud-sdk/lib/third_party/urllib3/util/connection.py", line 72, in create_connection
    for res in socket.getaddrinfo(host, port, family, socket.SOCK_STREAM):
               ^^^^^^^^^^^^^^^^^^^^^^^^^^^^^^^^^^^^^^^^^^^^^^^^^^^^^^^^^^
  File "/opt/homebrew/Cellar/python@3.11/3.11.2_1/Frameworks/Python.framework/Versions/3.11/lib/python3.11/socket.py", line 962, in getaddrinfo
    for res in _socket.getaddrinfo(host, port, family, type, proto, flags):
               ^^^^^^^^^^^^^^^^^^^^^^^^^^^^^^^^^^^^^^^^^^^^^^^^^^^^^^^^^^^
socket.gaierror: [Errno 8] nodename nor servname provided, or not known

During handling of the above exception, another exception occurred:

Traceback (most recent call last):
  File "/Users/inelpandzic/Dev/Workspace/tools/google-cloud-sdk/lib/third_party/urllib3/connectionpool.py", line 703, in urlopen
    httplib_response = self._make_request(
                       ^^^^^^^^^^^^^^^^^^^
  File "/Users/inelpandzic/Dev/Workspace/tools/google-cloud-sdk/lib/third_party/urllib3/connectionpool.py", line 386, in _make_request
    self._validate_conn(conn)
  File "/Users/inelpandzic/Dev/Workspace/tools/google-cloud-sdk/lib/third_party/urllib3/connectionpool.py", line 1043, in _validate_conn
    conn.connect()
  File "/Users/inelpandzic/Dev/Workspace/tools/google-cloud-sdk/lib/third_party/urllib3/connection.py", line 358, in connect
    self.sock = conn = self._new_conn()
                       ^^^^^^^^^^^^^^^^
  File "/Users/inelpandzic/Dev/Workspace/tools/google-cloud-sdk/lib/third_party/urllib3/connection.py", line 186, in _new_conn
    raise NewConnectionError(
urllib3.exceptions.NewConnectionError: <urllib3.connection.HTTPSConnection object at 0x106f47d10>: Failed to establish a new connection: [Errno 8] nodename nor servname provided, or not known

During handling of the above exception, another exception occurred:

Traceback (most recent call last):
  File "/Users/inelpandzic/Dev/Workspace/tools/google-cloud-sdk/lib/third_party/requests/adapters.py", line 439, in send
    resp = conn.urlopen(
           ^^^^^^^^^^^^^
  File "/Users/inelpandzic/Dev/Workspace/tools/google-cloud-sdk/lib/third_party/urllib3/connectionpool.py", line 785, in urlopen
    retries = retries.increment(
              ^^^^^^^^^^^^^^^^^^
  File "/Users/inelpandzic/Dev/Workspace/tools/google-cloud-sdk/lib/third_party/urllib3/util/retry.py", line 592, in increment
    raise MaxRetryError(_pool, url, error or ResponseError(cause))
urllib3.exceptions.MaxRetryError: HTTPSConnectionPool(host='oauth2.googleapis.com', port=443): Max retries exceeded with url: /token (Caused by NewConnectionError('<urllib3.connection.HTTPSConnection object at 0x106f47d10>: Failed to establish a new connection: [Errno 8] nodename nor servname provided, or not known'))

During handling of the above exception, another exception occurred:

Traceback (most recent call last):
  File "/Users/inelpandzic/Dev/Workspace/tools/google-cloud-sdk/lib/third_party/google/auth/transport/requests.py", line 193, in __call__
    response = self.session.request(
               ^^^^^^^^^^^^^^^^^^^^^
  File "/Users/inelpandzic/Dev/Workspace/tools/google-cloud-sdk/lib/googlecloudsdk/core/transport.py", line 260, in WrappedRequest
    response = orig_request(*modified_args, **modified_kwargs)
               ^^^^^^^^^^^^^^^^^^^^^^^^^^^^^^^^^^^^^^^^^^^^^^^
  File "/Users/inelpandzic/Dev/Workspace/tools/google-cloud-sdk/lib/googlecloudsdk/core/requests.py", line 246, in WrappedRequest
    return orig_request_method(*args, **kwargs)
           ^^^^^^^^^^^^^^^^^^^^^^^^^^^^^^^^^^^^
  File "/Users/inelpandzic/Dev/Workspace/tools/google-cloud-sdk/lib/third_party/requests/sessions.py", line 542, in request
    resp = self.send(prep, **send_kwargs)
           ^^^^^^^^^^^^^^^^^^^^^^^^^^^^^^
  File "/Users/inelpandzic/Dev/Workspace/tools/google-cloud-sdk/lib/third_party/requests/sessions.py", line 655, in send
    r = adapter.send(request, **kwargs)
        ^^^^^^^^^^^^^^^^^^^^^^^^^^^^^^^
  File "/Users/inelpandzic/Dev/Workspace/tools/google-cloud-sdk/lib/third_party/requests/adapters.py", line 516, in send
    raise ConnectionError(e, request=request)
requests.exceptions.ConnectionError: HTTPSConnectionPool(host='oauth2.googleapis.com', port=443): Max retries exceeded with url: /token (Caused by NewConnectionError('<urllib3.connection.HTTPSConnection object at 0x106f47d10>: Failed to establish a new connection: [Errno 8] nodename nor servname provided, or not known'))

The above exception was the direct cause of the following exception:

Traceback (most recent call last):
  File "/Users/inelpandzic/Dev/Workspace/tools/google-cloud-sdk/lib/googlecloudsdk/calliope/cli.py", line 987, in Execute
    resources = calliope_command.Run(cli=self, args=args)
                ^^^^^^^^^^^^^^^^^^^^^^^^^^^^^^^^^^^^^^^^^
  File "/Users/inelpandzic/Dev/Workspace/tools/google-cloud-sdk/lib/googlecloudsdk/calliope/backend.py", line 807, in Run
    resources = command_instance.Run(args)
                ^^^^^^^^^^^^^^^^^^^^^^^^^^
  File "/Users/inelpandzic/Dev/Workspace/tools/google-cloud-sdk/lib/surface/projects/describe.py", line 51, in Run
    return projects_api.Get(project_ref)
           ^^^^^^^^^^^^^^^^^^^^^^^^^^^^^
  File "/Users/inelpandzic/Dev/Workspace/tools/google-cloud-sdk/lib/googlecloudsdk/api_lib/cloudresourcemanager/projects_api.py", line 124, in Get
    client = projects_util.GetClient(api_version)
             ^^^^^^^^^^^^^^^^^^^^^^^^^^^^^^^^^^^^
  File "/Users/inelpandzic/Dev/Workspace/tools/google-cloud-sdk/lib/googlecloudsdk/api_lib/cloudresourcemanager/projects_util.py", line 56, in GetClient
    return apis.GetClientInstance(_API_NAME, version)
           ^^^^^^^^^^^^^^^^^^^^^^^^^^^^^^^^^^^^^^^^^^
  File "/Users/inelpandzic/Dev/Workspace/tools/google-cloud-sdk/lib/googlecloudsdk/api_lib/util/apis.py", line 261, in GetClientInstance
    return apis_internal._GetClientInstance(
           ^^^^^^^^^^^^^^^^^^^^^^^^^^^^^^^^^
  File "/Users/inelpandzic/Dev/Workspace/tools/google-cloud-sdk/lib/googlecloudsdk/api_lib/util/apis_internal.py", line 169, in _GetClientInstance
    http_client = transports.GetApitoolsTransport(
                  ^^^^^^^^^^^^^^^^^^^^^^^^^^^^^^^^
  File "/Users/inelpandzic/Dev/Workspace/tools/google-cloud-sdk/lib/googlecloudsdk/core/credentials/transports.py", line 80, in GetApitoolsTransport
    session = requests.GetSession(
              ^^^^^^^^^^^^^^^^^^^^
  File "/Users/inelpandzic/Dev/Workspace/tools/google-cloud-sdk/lib/googlecloudsdk/core/credentials/requests.py", line 82, in GetSession
    session = request_wrapper.WrapQuota(session, enable_resource_quota,
              ^^^^^^^^^^^^^^^^^^^^^^^^^^^^^^^^^^^^^^^^^^^^^^^^^^^^^^^^^
  File "/Users/inelpandzic/Dev/Workspace/tools/google-cloud-sdk/lib/googlecloudsdk/core/credentials/requests.py", line 127, in WrapQuota
    quota_project = self.QuotaProject(enable_resource_quota,
                    ^^^^^^^^^^^^^^^^^^^^^^^^^^^^^^^^^^^^^^^^
  File "/Users/inelpandzic/Dev/Workspace/tools/google-cloud-sdk/lib/googlecloudsdk/core/credentials/transport.py", line 54, in QuotaProject
    creds = store.LoadIfEnabled(allow_account_impersonation, use_google_auth)
            ^^^^^^^^^^^^^^^^^^^^^^^^^^^^^^^^^^^^^^^^^^^^^^^^^^^^^^^^^^^^^^^^^
  File "/Users/inelpandzic/Dev/Workspace/tools/google-cloud-sdk/lib/googlecloudsdk/core/credentials/store.py", line 455, in LoadIfEnabled
    return Load(
           ^^^^^
  File "/Users/inelpandzic/Dev/Workspace/tools/google-cloud-sdk/lib/googlecloudsdk/core/credentials/store.py", line 565, in Load
    cred = _Load(
           ^^^^^^
  File "/Users/inelpandzic/Dev/Workspace/tools/google-cloud-sdk/lib/googlecloudsdk/core/credentials/store.py", line 747, in _Load
    RefreshIfAlmostExpire(cred)
  File "/Users/inelpandzic/Dev/Workspace/tools/google-cloud-sdk/lib/googlecloudsdk/core/credentials/store.py", line 1025, in RefreshIfAlmostExpire
    RefreshIfExpireWithinWindow(credentials, window=_CREDENTIALS_EXPIRY_WINDOW)
  File "/Users/inelpandzic/Dev/Workspace/tools/google-cloud-sdk/lib/googlecloudsdk/core/credentials/store.py", line 1021, in RefreshIfExpireWithinWindow
    Refresh(credentials)
  File "/Users/inelpandzic/Dev/Workspace/tools/google-cloud-sdk/lib/googlecloudsdk/core/credentials/store.py", line 787, in Refresh
    _RefreshGoogleAuth(credentials, is_impersonated_credential,
  File "/Users/inelpandzic/Dev/Workspace/tools/google-cloud-sdk/lib/googlecloudsdk/core/credentials/store.py", line 902, in _RefreshGoogleAuth
    credentials.refresh(request_client)
  File "/Users/inelpandzic/Dev/Workspace/tools/google-cloud-sdk/lib/googlecloudsdk/core/credentials/creds.py", line 634, in _WrappedRefresh
    orig_refresh(request)
  File "/Users/inelpandzic/Dev/Workspace/tools/google-cloud-sdk/lib/googlecloudsdk/core/credentials/google_auth_credentials.py", line 105, in refresh
    return self._Refresh(request)
           ^^^^^^^^^^^^^^^^^^^^^^
  File "/Users/inelpandzic/Dev/Workspace/tools/google-cloud-sdk/lib/googlecloudsdk/core/credentials/google_auth_credentials.py", line 150, in _Refresh
    access_token, refresh_token, expiry, grant_response = _RefreshGrant(
                                                          ^^^^^^^^^^^^^^
  File "/Users/inelpandzic/Dev/Workspace/tools/google-cloud-sdk/lib/googlecloudsdk/core/credentials/google_auth_credentials.py", line 245, in _RefreshGrant
    response_data = _TokenEndpointRequestWithRetry(request, token_uri, body)
                    ^^^^^^^^^^^^^^^^^^^^^^^^^^^^^^^^^^^^^^^^^^^^^^^^^^^^^^^^
  File "/Users/inelpandzic/Dev/Workspace/tools/google-cloud-sdk/lib/googlecloudsdk/core/util/retry.py", line 312, in DecoratedFunction
    exceptions.reraise(to_reraise[1], tb=to_reraise[2])
  File "/Users/inelpandzic/Dev/Workspace/tools/google-cloud-sdk/lib/googlecloudsdk/core/exceptions.py", line 146, in reraise
    six.reraise(type(exc_value), exc_value, tb)
  File "/Users/inelpandzic/Dev/Workspace/tools/google-cloud-sdk/lib/third_party/six/__init__.py", line 719, in reraise
    raise value
  File "/Users/inelpandzic/Dev/Workspace/tools/google-cloud-sdk/lib/googlecloudsdk/core/util/retry.py", line 182, in TryFunc
    return func(*args, **kwargs), None
           ^^^^^^^^^^^^^^^^^^^^^
  File "/Users/inelpandzic/Dev/Workspace/tools/google-cloud-sdk/lib/googlecloudsdk/core/credentials/google_auth_credentials.py", line 301, in _TokenEndpointRequestWithRetry
    response = request(method='POST', url=token_uri, headers=headers, body=body)
               ^^^^^^^^^^^^^^^^^^^^^^^^^^^^^^^^^^^^^^^^^^^^^^^^^^^^^^^^^^^^^^^^^
  File "/Users/inelpandzic/Dev/Workspace/tools/google-cloud-sdk/lib/third_party/google/auth/transport/requests.py", line 199, in __call__
    six.raise_from(new_exc, caught_exc)
  File "<string>", line 3, in raise_from
google.auth.exceptions.TransportError: HTTPSConnectionPool(host='oauth2.googleapis.com', port=443): Max retries exceeded with url: /token (Caused by NewConnectionError('<urllib3.connection.HTTPSConnection object at 0x106f47d10>: Failed to establish a new connection: [Errno 8] nodename nor servname provided, or not known'))
2023-07-06 13:11:04,875 ERROR    root            (gcloud.projects.describe) There was a problem refreshing your current auth tokens: HTTPSConnectionPool(host='oauth2.googleapis.com', port=443): Max retries exceeded with url: /token (Caused by NewConnectionError('<urllib3.connection.HTTPSConnection object at 0x106f47d10>: Failed to establish a new connection: [Errno 8] nodename nor servname provided, or not known'))
Please run:

  $ gcloud auth login

to obtain new credentials.

If you have already logged in with a different account:

    $ gcloud config set account ACCOUNT

to select an already authenticated account to use.
2023-07-06 13:11:04,881 DEBUG    root            Metrics reporting process started...
